==============================================
  SCAIE - Sistema Agente Conversacional       
  Script de Ejecuci√≥n Simple                  
==============================================

[0;34m[INFO][0m Starting SCAIE application...
[0;34m[INFO][0m Activating virtual environment...
[0;32m[SUCCESS][0m Virtual environment activated
[0;34m[INFO][0m Checking environment configuration...
[0;32m[SUCCESS][0m .env file found
[0;34m[INFO][0m Checking database...
[0;32m[SUCCESS][0m Database found
[0;34m[INFO][0m Checking for processes on port 8003...
[0;32m[SUCCESS][0m No processes found on port 8003

==============================================
  SCAIE is ready to run!                      
==============================================

[0;32m[SUCCESS][0m Starting the application...
[0;32m[SUCCESS][0m The application will be available at:
    Web Interface: http://localhost:8003
    API Documentation: http://localhost:8003/docs
    Health Check: http://localhost:8003/health

[1;33m[WARNING][0m Press Ctrl+C to stop the application

/Users/arturopinzon/Desktop/scAIe - Sistema Agente/scaie_crm/venv/lib/python3.9/site-packages/pydantic/_internal/_config.py:373: UserWarning: Valid config keys have changed in V2:
* 'orm_mode' has been renamed to 'from_attributes'
  warnings.warn(message, UserWarning)
INFO:     Will watch for changes in these directories: ['/Users/arturopinzon/Desktop/scAIe - Sistema Agente/scaie_crm/backend/src/scaie']
INFO:     Uvicorn running on http://0.0.0.0:8003 (Press CTRL+C to quit)
INFO:     Started reloader process [41500] using StatReload
/Users/arturopinzon/Desktop/scAIe - Sistema Agente/scaie_crm/venv/lib/python3.9/site-packages/pydantic/_internal/_config.py:373: UserWarning: Valid config keys have changed in V2:
* 'orm_mode' has been renamed to 'from_attributes'
  warnings.warn(message, UserWarning)
INFO:     Started server process [41523]
INFO:     Waiting for application startup.
INFO:     Application startup complete.
INFO:     127.0.0.1:59376 - "GET /api/contacts/ HTTP/1.1" 500 Internal Server Error
ERROR:    Exception in ASGI application
Traceback (most recent call last):
  File "/Users/arturopinzon/Desktop/scAIe - Sistema Agente/scaie_crm/venv/lib/python3.9/site-packages/sqlalchemy/engine/base.py", line 1961, in _exec_single_context
    self.dialect.do_execute(
  File "/Users/arturopinzon/Desktop/scAIe - Sistema Agente/scaie_crm/venv/lib/python3.9/site-packages/sqlalchemy/engine/default.py", line 944, in do_execute
    cursor.execute(statement, parameters)
sqlite3.OperationalError: no such table: contacts

The above exception was the direct cause of the following exception:

Traceback (most recent call last):
  File "/Users/arturopinzon/Desktop/scAIe - Sistema Agente/scaie_crm/venv/lib/python3.9/site-packages/uvicorn/protocols/http/h11_impl.py", line 403, in run_asgi
    result = await app(  # type: ignore[func-returns-value]
  File "/Users/arturopinzon/Desktop/scAIe - Sistema Agente/scaie_crm/venv/lib/python3.9/site-packages/uvicorn/middleware/proxy_headers.py", line 60, in __call__
    return await self.app(scope, receive, send)
  File "/Users/arturopinzon/Desktop/scAIe - Sistema Agente/scaie_crm/venv/lib/python3.9/site-packages/fastapi/applications.py", line 1054, in __call__
    await super().__call__(scope, receive, send)
  File "/Users/arturopinzon/Desktop/scAIe - Sistema Agente/scaie_crm/venv/lib/python3.9/site-packages/starlette/applications.py", line 113, in __call__
    await self.middleware_stack(scope, receive, send)
  File "/Users/arturopinzon/Desktop/scAIe - Sistema Agente/scaie_crm/venv/lib/python3.9/site-packages/starlette/middleware/errors.py", line 186, in __call__
    raise exc
  File "/Users/arturopinzon/Desktop/scAIe - Sistema Agente/scaie_crm/venv/lib/python3.9/site-packages/starlette/middleware/errors.py", line 164, in __call__
    await self.app(scope, receive, _send)
  File "/Users/arturopinzon/Desktop/scAIe - Sistema Agente/scaie_crm/venv/lib/python3.9/site-packages/starlette/middleware/cors.py", line 85, in __call__
    await self.app(scope, receive, send)
  File "/Users/arturopinzon/Desktop/scAIe - Sistema Agente/scaie_crm/venv/lib/python3.9/site-packages/starlette/middleware/exceptions.py", line 63, in __call__
    await wrap_app_handling_exceptions(self.app, conn)(scope, receive, send)
  File "/Users/arturopinzon/Desktop/scAIe - Sistema Agente/scaie_crm/venv/lib/python3.9/site-packages/starlette/_exception_handler.py", line 53, in wrapped_app
    raise exc
  File "/Users/arturopinzon/Desktop/scAIe - Sistema Agente/scaie_crm/venv/lib/python3.9/site-packages/starlette/_exception_handler.py", line 42, in wrapped_app
    await app(scope, receive, sender)
  File "/Users/arturopinzon/Desktop/scAIe - Sistema Agente/scaie_crm/venv/lib/python3.9/site-packages/starlette/routing.py", line 716, in __call__
    await self.middleware_stack(scope, receive, send)
  File "/Users/arturopinzon/Desktop/scAIe - Sistema Agente/scaie_crm/venv/lib/python3.9/site-packages/starlette/routing.py", line 736, in app
    await route.handle(scope, receive, send)
  File "/Users/arturopinzon/Desktop/scAIe - Sistema Agente/scaie_crm/venv/lib/python3.9/site-packages/starlette/routing.py", line 290, in handle
    await self.app(scope, receive, send)
  File "/Users/arturopinzon/Desktop/scAIe - Sistema Agente/scaie_crm/venv/lib/python3.9/site-packages/starlette/routing.py", line 78, in app
    await wrap_app_handling_exceptions(app, request)(scope, receive, send)
  File "/Users/arturopinzon/Desktop/scAIe - Sistema Agente/scaie_crm/venv/lib/python3.9/site-packages/starlette/_exception_handler.py", line 53, in wrapped_app
    raise exc
  File "/Users/arturopinzon/Desktop/scAIe - Sistema Agente/scaie_crm/venv/lib/python3.9/site-packages/starlette/_exception_handler.py", line 42, in wrapped_app
    await app(scope, receive, sender)
  File "/Users/arturopinzon/Desktop/scAIe - Sistema Agente/scaie_crm/venv/lib/python3.9/site-packages/starlette/routing.py", line 75, in app
    response = await f(request)
  File "/Users/arturopinzon/Desktop/scAIe - Sistema Agente/scaie_crm/venv/lib/python3.9/site-packages/fastapi/routing.py", line 302, in app
    raw_response = await run_endpoint_function(
  File "/Users/arturopinzon/Desktop/scAIe - Sistema Agente/scaie_crm/venv/lib/python3.9/site-packages/fastapi/routing.py", line 215, in run_endpoint_function
    return await run_in_threadpool(dependant.call, **values)
  File "/Users/arturopinzon/Desktop/scAIe - Sistema Agente/scaie_crm/venv/lib/python3.9/site-packages/starlette/concurrency.py", line 38, in run_in_threadpool
    return await anyio.to_thread.run_sync(func)
  File "/Users/arturopinzon/Desktop/scAIe - Sistema Agente/scaie_crm/venv/lib/python3.9/site-packages/anyio/to_thread.py", line 56, in run_sync
    return await get_async_backend().run_sync_in_worker_thread(
  File "/Users/arturopinzon/Desktop/scAIe - Sistema Agente/scaie_crm/venv/lib/python3.9/site-packages/anyio/_backends/_asyncio.py", line 2476, in run_sync_in_worker_thread
    return await future
  File "/Users/arturopinzon/Desktop/scAIe - Sistema Agente/scaie_crm/venv/lib/python3.9/site-packages/anyio/_backends/_asyncio.py", line 967, in run
    result = context.run(func, *args)
  File "/Users/arturopinzon/Desktop/scAIe - Sistema Agente/scaie_crm/backend/src/scaie/app/api/endpoints/contacts.py", line 23, in list_contacts
    return contact_service.get_contacts(db, skip=skip, limit=limit, search=search)
  File "/Users/arturopinzon/Desktop/scAIe - Sistema Agente/scaie_crm/backend/src/scaie/app/services/contact_service.py", line 43, in get_contacts
    total = query.count()
  File "/Users/arturopinzon/Desktop/scAIe - Sistema Agente/scaie_crm/venv/lib/python3.9/site-packages/sqlalchemy/orm/query.py", line 3146, in count
    self._legacy_from_self(col).enable_eagerloads(False).scalar()
  File "/Users/arturopinzon/Desktop/scAIe - Sistema Agente/scaie_crm/venv/lib/python3.9/site-packages/sqlalchemy/orm/query.py", line 2835, in scalar
    ret = self.one()
  File "/Users/arturopinzon/Desktop/scAIe - Sistema Agente/scaie_crm/venv/lib/python3.9/site-packages/sqlalchemy/orm/query.py", line 2808, in one
    return self._iter().one()  # type: ignore
  File "/Users/arturopinzon/Desktop/scAIe - Sistema Agente/scaie_crm/venv/lib/python3.9/site-packages/sqlalchemy/orm/query.py", line 2857, in _iter
    result: Union[ScalarResult[_T], Result[_T]] = self.session.execute(
  File "/Users/arturopinzon/Desktop/scAIe - Sistema Agente/scaie_crm/venv/lib/python3.9/site-packages/sqlalchemy/orm/session.py", line 2365, in execute
    return self._execute_internal(
  File "/Users/arturopinzon/Desktop/scAIe - Sistema Agente/scaie_crm/venv/lib/python3.9/site-packages/sqlalchemy/orm/session.py", line 2251, in _execute_internal
    result: Result[Any] = compile_state_cls.orm_execute_statement(
  File "/Users/arturopinzon/Desktop/scAIe - Sistema Agente/scaie_crm/venv/lib/python3.9/site-packages/sqlalchemy/orm/context.py", line 306, in orm_execute_statement
    result = conn.execute(
  File "/Users/arturopinzon/Desktop/scAIe - Sistema Agente/scaie_crm/venv/lib/python3.9/site-packages/sqlalchemy/engine/base.py", line 1413, in execute
    return meth(
  File "/Users/arturopinzon/Desktop/scAIe - Sistema Agente/scaie_crm/venv/lib/python3.9/site-packages/sqlalchemy/sql/elements.py", line 526, in _execute_on_connection
    return connection._execute_clauseelement(
  File "/Users/arturopinzon/Desktop/scAIe - Sistema Agente/scaie_crm/venv/lib/python3.9/site-packages/sqlalchemy/engine/base.py", line 1635, in _execute_clauseelement
    ret = self._execute_context(
  File "/Users/arturopinzon/Desktop/scAIe - Sistema Agente/scaie_crm/venv/lib/python3.9/site-packages/sqlalchemy/engine/base.py", line 1840, in _execute_context
    return self._exec_single_context(
  File "/Users/arturopinzon/Desktop/scAIe - Sistema Agente/scaie_crm/venv/lib/python3.9/site-packages/sqlalchemy/engine/base.py", line 1980, in _exec_single_context
    self._handle_dbapi_exception(
  File "/Users/arturopinzon/Desktop/scAIe - Sistema Agente/scaie_crm/venv/lib/python3.9/site-packages/sqlalchemy/engine/base.py", line 2349, in _handle_dbapi_exception
    raise sqlalchemy_exception.with_traceback(exc_info[2]) from e
  File "/Users/arturopinzon/Desktop/scAIe - Sistema Agente/scaie_crm/venv/lib/python3.9/site-packages/sqlalchemy/engine/base.py", line 1961, in _exec_single_context
    self.dialect.do_execute(
  File "/Users/arturopinzon/Desktop/scAIe - Sistema Agente/scaie_crm/venv/lib/python3.9/site-packages/sqlalchemy/engine/default.py", line 944, in do_execute
    cursor.execute(statement, parameters)
sqlalchemy.exc.OperationalError: (sqlite3.OperationalError) no such table: contacts
[SQL: SELECT count(*) AS count_1 
FROM (SELECT contacts.id AS contacts_id, contacts.name AS contacts_name, contacts.phone AS contacts_phone, contacts.email AS contacts_email, contacts.company AS contacts_company, contacts.notes AS contacts_notes, contacts.interest_level AS contacts_interest_level, contacts.telegram_user_id AS contacts_telegram_user_id, contacts.platform_user_id AS contacts_platform_user_id, contacts.created_at AS contacts_created_at, contacts.updated_at AS contacts_updated_at 
FROM contacts) AS anon_1]
(Background on this error at: https://sqlalche.me/e/20/e3q8)
INFO:     127.0.0.1:59378 - "GET /health HTTP/1.1" 200 OK
INFO:     127.0.0.1:59384 - "GET /api/contacts/ HTTP/1.1" 200 OK
INFO:     127.0.0.1:59387 - "GET /health HTTP/1.1" 200 OK
INFO:     127.0.0.1:59392 - "POST /api/contacts/ HTTP/1.1" 422 Unprocessable Entity
INFO:     127.0.0.1:59400 - "POST /api/contacts/ HTTP/1.1" 200 OK
INFO:     127.0.0.1:59405 - "GET /api/contacts/ HTTP/1.1" 200 OK
INFO:     127.0.0.1:59409 - "GET / HTTP/1.1" 200 OK
INFO:     127.0.0.1:59431 - "GET /health HTTP/1.1" 200 OK
INFO:     127.0.0.1:59434 - "GET /api/contacts/ HTTP/1.1" 200 OK
INFO:     127.0.0.1:59436 - "GET / HTTP/1.1" 200 OK
INFO:     127.0.0.1:59445 - "GET / HTTP/1.1" 200 OK
INFO:     127.0.0.1:59445 - "GET /assets/index.9c91fcfe.js HTTP/1.1" 200 OK
INFO:     127.0.0.1:59446 - "GET /assets/index.58a9d414.css HTTP/1.1" 200 OK
INFO:     127.0.0.1:59446 - "GET /api/agent/stats HTTP/1.1" 200 OK
INFO:     127.0.0.1:59450 - "GET /api/contacts/stats HTTP/1.1" 422 Unprocessable Entity
INFO:     127.0.0.1:59449 - "GET /api/contacts/?page=1&size=10 HTTP/1.1" 200 OK
INFO:     127.0.0.1:59454 - "GET /api/agent/stats HTTP/1.1" 200 OK
INFO:app.services.llm_service:Generando respuesta para el mensaje: hola
INFO:httpx:HTTP Request: POST https://dashscope-intl.aliyuncs.com/compatible-mode/v1/chat/completions "HTTP/1.1 200 OK"
INFO:app.services.llm_service:Respuesta del modelo: Hola, ¬øen qu√© puedo ayudarte?
INFO:     127.0.0.1:59457 - "POST /api/chat/ HTTP/1.1" 200 OK
