==============================================
  SCAIE - Sistema Agente Conversacional       
  Script de Ejecuci√≥n Simple                  
==============================================

[0;34m[INFO][0m Starting SCAIE application...
[0;34m[INFO][0m Activating virtual environment...
[0;32m[SUCCESS][0m Virtual environment activated
[0;34m[INFO][0m Checking environment configuration...
[0;32m[SUCCESS][0m .env file found
[0;34m[INFO][0m Checking database...
[0;32m[SUCCESS][0m Database found
[0;34m[INFO][0m Checking for processes on port 8003...
[0;32m[SUCCESS][0m No processes found on port 8003

==============================================
  SCAIE is ready to run!                      
==============================================

[0;32m[SUCCESS][0m Starting the application...
[0;32m[SUCCESS][0m The application will be available at:
    Web Interface: http://localhost:8003
    API Documentation: http://localhost:8003/docs
    Health Check: http://localhost:8003/health

[1;33m[WARNING][0m Press Ctrl+C to stop the application

/Users/arturopinzon/Desktop/scAIe - Sistema Agente/scaie_crm/venv/lib/python3.9/site-packages/pydantic/_internal/_config.py:373: UserWarning: Valid config keys have changed in V2:
* 'orm_mode' has been renamed to 'from_attributes'
  warnings.warn(message, UserWarning)
INFO:     Will watch for changes in these directories: ['/Users/arturopinzon/Desktop/scAIe - Sistema Agente/scaie_crm/backend/src/scaie']
INFO:     Uvicorn running on http://0.0.0.0:8003 (Press CTRL+C to quit)
INFO:     Started reloader process [97052] using StatReload
/Users/arturopinzon/Desktop/scAIe - Sistema Agente/scaie_crm/venv/lib/python3.9/site-packages/pydantic/_internal/_config.py:373: UserWarning: Valid config keys have changed in V2:
* 'orm_mode' has been renamed to 'from_attributes'
  warnings.warn(message, UserWarning)
INFO:     Started server process [97196]
INFO:     Waiting for application startup.
INFO:     Application startup complete.
INFO:     127.0.0.1:58598 - "GET /health HTTP/1.1" 200 OK
INFO:app.services.llm_service:Generando respuesta para el mensaje: ¬øQu√© es el workshop de eficiencia con IA?
INFO:httpx:HTTP Request: POST https://dashscope-intl.aliyuncs.com/compatible-mode/v1/chat/completions "HTTP/1.1 200 OK"
INFO:app.services.llm_service:Respuesta del modelo: Es un taller pr√°ctico donde aprendes a usar herramientas de inteligencia artificial sin necesidad de programar, para automatizar tareas y mejorar la productividad en tu equipo.  

¬øTe gustar√≠a saber c√≥mo podr√≠a aplicarse en tu √°rea o negocio?
INFO:     127.0.0.1:58609 - "POST /api/chat/ HTTP/1.1" 200 OK
INFO:app.services.llm_service:Generando respuesta para el mensaje: ¬øCu√°nto cuesta el workshop?
INFO:httpx:HTTP Request: POST https://dashscope-intl.aliyuncs.com/compatible-mode/v1/chat/completions "HTTP/1.1 200 OK"
INFO:app.services.llm_service:Respuesta del modelo: El workshop tiene un costo de $4,500 MXN por persona, pero si te inscribes antes del 15 de agosto, tienes un descuento del 20%.  

¬øTe gustar√≠a que te env√≠e el temario completo o hablar de fechas disponibles?
INFO:     127.0.0.1:58617 - "POST /api/chat/ HTTP/1.1" 200 OK
INFO:app.services.llm_service:Generando respuesta para el mensaje: ¬øCu√°nto cuesta el workshop?
INFO:httpx:HTTP Request: POST https://dashscope-intl.aliyuncs.com/compatible-mode/v1/chat/completions "HTTP/1.1 200 OK"
INFO:app.services.llm_service:Respuesta del modelo: El workshop tiene un costo de $4,500 MXN por persona. Si te inscribes antes del 15 de agosto, aplicas para un descuento del 20%.  

¬øTe gustar√≠a que te comparta m√°s detalles o agendemos una pl√°tica?
INFO:     127.0.0.1:58624 - "POST /api/chat/ HTTP/1.1" 200 OK
INFO:     127.0.0.1:58641 - "GET /chat HTTP/1.1" 200 OK
INFO:     127.0.0.1:58641 - "GET /assets/index.58a9d414.css HTTP/1.1" 200 OK
INFO:     127.0.0.1:58642 - "GET /assets/index.9c91fcfe.js HTTP/1.1" 200 OK
INFO:app.services.llm_service:Generando respuesta para el mensaje: hola
INFO:httpx:HTTP Request: POST https://dashscope-intl.aliyuncs.com/compatible-mode/v1/chat/completions "HTTP/1.1 200 OK"
INFO:app.services.llm_service:Respuesta del modelo: Hola, ¬øen qu√© puedo ayudarte?
INFO:     127.0.0.1:58641 - "POST /api/chat/ HTTP/1.1" 200 OK
INFO:app.services.llm_service:Generando respuesta para el mensaje: quiero saber sobre el workshop 
INFO:httpx:HTTP Request: POST https://dashscope-intl.aliyuncs.com/compatible-mode/v1/chat/completions "HTTP/1.1 200 OK"
INFO:app.services.llm_service:Respuesta del modelo: El workshop "S√© m√°s eficiente con IA" te ense√±a a usar herramientas de inteligencia artificial sin c√≥digo, para automatizar tareas y mejorar la productividad en tu equipo.  

¬øTe gustar√≠a saber m√°s sobre el temario o fechas disponibles?
INFO:     127.0.0.1:58651 - "POST /api/chat/ HTTP/1.1" 200 OK
INFO:app.services.llm_service:Generando respuesta para el mensaje: hablame del temario o como se usa, que me beneficia ?
INFO:httpx:HTTP Request: POST https://dashscope-intl.aliyuncs.com/compatible-mode/v1/chat/completions "HTTP/1.1 200 OK"
INFO:app.services.llm_service:Respuesta del modelo: El temario incluye:  
1. Introducci√≥n a la IA sin c√≥digo  
2. Herramientas pr√°cticas para automatizar tareas  
3. Casos de uso por departamento (ventas, marketing, operaciones)  
4. An√°lisis de datos con IA accesible  
5. Proyectos reales en equipo  

Te beneficia al mejorar la productividad de tu equipo sin necesidad de experiencia t√©cnica previa.  

¬øQuieres que te env√≠e el temario completo o agendamos una pl√°tica?
INFO:     127.0.0.1:58654 - "POST /api/chat/ HTTP/1.1" 200 OK
INFO:app.services.llm_service:Generando respuesta para el mensaje: agendemos una conversacion
INFO:httpx:HTTP Request: POST https://dashscope-intl.aliyuncs.com/compatible-mode/v1/chat/completions "HTTP/1.1 200 OK"
INFO:app.services.llm_service:Respuesta del modelo: Perfecto, ¬øqu√© d√≠a y hora te quedan mejor para platicar sobre el workshop?
INFO:     127.0.0.1:58661 - "POST /api/chat/ HTTP/1.1" 200 OK
INFO:app.services.llm_service:Generando respuesta para el mensaje: jueves a las 11 de la noche
INFO:httpx:HTTP Request: POST https://dashscope-intl.aliyuncs.com/compatible-mode/v1/chat/completions "HTTP/1.1 200 OK"
INFO:app.services.llm_service:Respuesta del modelo: El jueves a las 11 PM est√° disponible. Te enviar√© un recordatorio con el enlace de la reuni√≥n.  

¬øNecesitas que te comparta algo adicional antes de nuestra pl√°tica?
INFO:     127.0.0.1:58665 - "POST /api/chat/ HTTP/1.1" 200 OK
INFO:app.services.llm_service:Generando respuesta para el mensaje: no, muchas gracias 
INFO:httpx:HTTP Request: POST https://dashscope-intl.aliyuncs.com/compatible-mode/v1/chat/completions "HTTP/1.1 200 OK"
INFO:app.services.llm_service:Respuesta del modelo: Perfecto, te confirmo la reuni√≥n el jueves a las 11 PM. Nos vemos ah√≠.
INFO:     127.0.0.1:58669 - "POST /api/chat/ HTTP/1.1" 200 OK
INFO:     127.0.0.1:58673 - "GET /api/agent/stats HTTP/1.1" 200 OK
INFO:     127.0.0.1:58674 - "GET /api/contacts/stats HTTP/1.1" 422 Unprocessable Entity
INFO:     127.0.0.1:58673 - "GET /api/contacts/?page=1&size=10 HTTP/1.1" 500 Internal Server Error
ERROR:    Exception in ASGI application
Traceback (most recent call last):
  File "/Users/arturopinzon/Desktop/scAIe - Sistema Agente/scaie_crm/venv/lib/python3.9/site-packages/uvicorn/protocols/http/h11_impl.py", line 403, in run_asgi
    result = await app(  # type: ignore[func-returns-value]
  File "/Users/arturopinzon/Desktop/scAIe - Sistema Agente/scaie_crm/venv/lib/python3.9/site-packages/uvicorn/middleware/proxy_headers.py", line 60, in __call__
    return await self.app(scope, receive, send)
  File "/Users/arturopinzon/Desktop/scAIe - Sistema Agente/scaie_crm/venv/lib/python3.9/site-packages/fastapi/applications.py", line 1054, in __call__
    await super().__call__(scope, receive, send)
  File "/Users/arturopinzon/Desktop/scAIe - Sistema Agente/scaie_crm/venv/lib/python3.9/site-packages/starlette/applications.py", line 113, in __call__
    await self.middleware_stack(scope, receive, send)
  File "/Users/arturopinzon/Desktop/scAIe - Sistema Agente/scaie_crm/venv/lib/python3.9/site-packages/starlette/middleware/errors.py", line 186, in __call__
    raise exc
  File "/Users/arturopinzon/Desktop/scAIe - Sistema Agente/scaie_crm/venv/lib/python3.9/site-packages/starlette/middleware/errors.py", line 164, in __call__
    await self.app(scope, receive, _send)
  File "/Users/arturopinzon/Desktop/scAIe - Sistema Agente/scaie_crm/venv/lib/python3.9/site-packages/starlette/middleware/cors.py", line 85, in __call__
    await self.app(scope, receive, send)
  File "/Users/arturopinzon/Desktop/scAIe - Sistema Agente/scaie_crm/venv/lib/python3.9/site-packages/starlette/middleware/exceptions.py", line 63, in __call__
    await wrap_app_handling_exceptions(self.app, conn)(scope, receive, send)
  File "/Users/arturopinzon/Desktop/scAIe - Sistema Agente/scaie_crm/venv/lib/python3.9/site-packages/starlette/_exception_handler.py", line 53, in wrapped_app
    raise exc
  File "/Users/arturopinzon/Desktop/scAIe - Sistema Agente/scaie_crm/venv/lib/python3.9/site-packages/starlette/_exception_handler.py", line 42, in wrapped_app
    await app(scope, receive, sender)
  File "/Users/arturopinzon/Desktop/scAIe - Sistema Agente/scaie_crm/venv/lib/python3.9/site-packages/starlette/routing.py", line 716, in __call__
    await self.middleware_stack(scope, receive, send)
  File "/Users/arturopinzon/Desktop/scAIe - Sistema Agente/scaie_crm/venv/lib/python3.9/site-packages/starlette/routing.py", line 736, in app
    await route.handle(scope, receive, send)
  File "/Users/arturopinzon/Desktop/scAIe - Sistema Agente/scaie_crm/venv/lib/python3.9/site-packages/starlette/routing.py", line 290, in handle
    await self.app(scope, receive, send)
  File "/Users/arturopinzon/Desktop/scAIe - Sistema Agente/scaie_crm/venv/lib/python3.9/site-packages/starlette/routing.py", line 78, in app
    await wrap_app_handling_exceptions(app, request)(scope, receive, send)
  File "/Users/arturopinzon/Desktop/scAIe - Sistema Agente/scaie_crm/venv/lib/python3.9/site-packages/starlette/_exception_handler.py", line 53, in wrapped_app
    raise exc
  File "/Users/arturopinzon/Desktop/scAIe - Sistema Agente/scaie_crm/venv/lib/python3.9/site-packages/starlette/_exception_handler.py", line 42, in wrapped_app
    await app(scope, receive, sender)
  File "/Users/arturopinzon/Desktop/scAIe - Sistema Agente/scaie_crm/venv/lib/python3.9/site-packages/starlette/routing.py", line 75, in app
    response = await f(request)
  File "/Users/arturopinzon/Desktop/scAIe - Sistema Agente/scaie_crm/venv/lib/python3.9/site-packages/fastapi/routing.py", line 328, in app
    content = await serialize_response(
  File "/Users/arturopinzon/Desktop/scAIe - Sistema Agente/scaie_crm/venv/lib/python3.9/site-packages/fastapi/routing.py", line 177, in serialize_response
    raise ResponseValidationError(
fastapi.exceptions.ResponseValidationError: 10 validation errors:
  {'type': 'string_type', 'loc': ('response', 'contacts', 3, 'phone'), 'msg': 'Input should be a valid string', 'input': None}
  {'type': 'string_type', 'loc': ('response', 'contacts', 4, 'phone'), 'msg': 'Input should be a valid string', 'input': None}
  {'type': 'string_type', 'loc': ('response', 'contacts', 5, 'phone'), 'msg': 'Input should be a valid string', 'input': None}
  {'type': 'string_type', 'loc': ('response', 'contacts', 6, 'phone'), 'msg': 'Input should be a valid string', 'input': None}
  {'type': 'string_type', 'loc': ('response', 'contacts', 7, 'phone'), 'msg': 'Input should be a valid string', 'input': None}
  {'type': 'string_type', 'loc': ('response', 'contacts', 8, 'phone'), 'msg': 'Input should be a valid string', 'input': None}
  {'type': 'string_type', 'loc': ('response', 'contacts', 9, 'phone'), 'msg': 'Input should be a valid string', 'input': None}
  {'type': 'string_type', 'loc': ('response', 'contacts', 10, 'phone'), 'msg': 'Input should be a valid string', 'input': None}
  {'type': 'string_type', 'loc': ('response', 'contacts', 11, 'phone'), 'msg': 'Input should be a valid string', 'input': None}
  {'type': 'string_type', 'loc': ('response', 'contacts', 12, 'phone'), 'msg': 'Input should be a valid string', 'input': None}

INFO:     127.0.0.1:58674 - "GET /api/contacts/?page=1&size=10 HTTP/1.1" 500 Internal Server Error
ERROR:    Exception in ASGI application
Traceback (most recent call last):
  File "/Users/arturopinzon/Desktop/scAIe - Sistema Agente/scaie_crm/venv/lib/python3.9/site-packages/uvicorn/protocols/http/h11_impl.py", line 403, in run_asgi
    result = await app(  # type: ignore[func-returns-value]
  File "/Users/arturopinzon/Desktop/scAIe - Sistema Agente/scaie_crm/venv/lib/python3.9/site-packages/uvicorn/middleware/proxy_headers.py", line 60, in __call__
    return await self.app(scope, receive, send)
  File "/Users/arturopinzon/Desktop/scAIe - Sistema Agente/scaie_crm/venv/lib/python3.9/site-packages/fastapi/applications.py", line 1054, in __call__
    await super().__call__(scope, receive, send)
  File "/Users/arturopinzon/Desktop/scAIe - Sistema Agente/scaie_crm/venv/lib/python3.9/site-packages/starlette/applications.py", line 113, in __call__
    await self.middleware_stack(scope, receive, send)
  File "/Users/arturopinzon/Desktop/scAIe - Sistema Agente/scaie_crm/venv/lib/python3.9/site-packages/starlette/middleware/errors.py", line 186, in __call__
    raise exc
  File "/Users/arturopinzon/Desktop/scAIe - Sistema Agente/scaie_crm/venv/lib/python3.9/site-packages/starlette/middleware/errors.py", line 164, in __call__
    await self.app(scope, receive, _send)
  File "/Users/arturopinzon/Desktop/scAIe - Sistema Agente/scaie_crm/venv/lib/python3.9/site-packages/starlette/middleware/cors.py", line 85, in __call__
    await self.app(scope, receive, send)
  File "/Users/arturopinzon/Desktop/scAIe - Sistema Agente/scaie_crm/venv/lib/python3.9/site-packages/starlette/middleware/exceptions.py", line 63, in __call__
    await wrap_app_handling_exceptions(self.app, conn)(scope, receive, send)
  File "/Users/arturopinzon/Desktop/scAIe - Sistema Agente/scaie_crm/venv/lib/python3.9/site-packages/starlette/_exception_handler.py", line 53, in wrapped_app
    raise exc
  File "/Users/arturopinzon/Desktop/scAIe - Sistema Agente/scaie_crm/venv/lib/python3.9/site-packages/starlette/_exception_handler.py", line 42, in wrapped_app
    await app(scope, receive, sender)
  File "/Users/arturopinzon/Desktop/scAIe - Sistema Agente/scaie_crm/venv/lib/python3.9/site-packages/starlette/routing.py", line 716, in __call__
    await self.middleware_stack(scope, receive, send)
  File "/Users/arturopinzon/Desktop/scAIe - Sistema Agente/scaie_crm/venv/lib/python3.9/site-packages/starlette/routing.py", line 736, in app
    await route.handle(scope, receive, send)
  File "/Users/arturopinzon/Desktop/scAIe - Sistema Agente/scaie_crm/venv/lib/python3.9/site-packages/starlette/routing.py", line 290, in handle
    await self.app(scope, receive, send)
  File "/Users/arturopinzon/Desktop/scAIe - Sistema Agente/scaie_crm/venv/lib/python3.9/site-packages/starlette/routing.py", line 78, in app
    await wrap_app_handling_exceptions(app, request)(scope, receive, send)
  File "/Users/arturopinzon/Desktop/scAIe - Sistema Agente/scaie_crm/venv/lib/python3.9/site-packages/starlette/_exception_handler.py", line 53, in wrapped_app
    raise exc
  File "/Users/arturopinzon/Desktop/scAIe - Sistema Agente/scaie_crm/venv/lib/python3.9/site-packages/starlette/_exception_handler.py", line 42, in wrapped_app
    await app(scope, receive, sender)
  File "/Users/arturopinzon/Desktop/scAIe - Sistema Agente/scaie_crm/venv/lib/python3.9/site-packages/starlette/routing.py", line 75, in app
    response = await f(request)
  File "/Users/arturopinzon/Desktop/scAIe - Sistema Agente/scaie_crm/venv/lib/python3.9/site-packages/fastapi/routing.py", line 328, in app
    content = await serialize_response(
  File "/Users/arturopinzon/Desktop/scAIe - Sistema Agente/scaie_crm/venv/lib/python3.9/site-packages/fastapi/routing.py", line 177, in serialize_response
    raise ResponseValidationError(
fastapi.exceptions.ResponseValidationError: 10 validation errors:
  {'type': 'string_type', 'loc': ('response', 'contacts', 3, 'phone'), 'msg': 'Input should be a valid string', 'input': None}
  {'type': 'string_type', 'loc': ('response', 'contacts', 4, 'phone'), 'msg': 'Input should be a valid string', 'input': None}
  {'type': 'string_type', 'loc': ('response', 'contacts', 5, 'phone'), 'msg': 'Input should be a valid string', 'input': None}
  {'type': 'string_type', 'loc': ('response', 'contacts', 6, 'phone'), 'msg': 'Input should be a valid string', 'input': None}
  {'type': 'string_type', 'loc': ('response', 'contacts', 7, 'phone'), 'msg': 'Input should be a valid string', 'input': None}
  {'type': 'string_type', 'loc': ('response', 'contacts', 8, 'phone'), 'msg': 'Input should be a valid string', 'input': None}
  {'type': 'string_type', 'loc': ('response', 'contacts', 9, 'phone'), 'msg': 'Input should be a valid string', 'input': None}
  {'type': 'string_type', 'loc': ('response', 'contacts', 10, 'phone'), 'msg': 'Input should be a valid string', 'input': None}
  {'type': 'string_type', 'loc': ('response', 'contacts', 11, 'phone'), 'msg': 'Input should be a valid string', 'input': None}
  {'type': 'string_type', 'loc': ('response', 'contacts', 12, 'phone'), 'msg': 'Input should be a valid string', 'input': None}

INFO:     127.0.0.1:58676 - "GET /api/contacts/?page=1&size=10 HTTP/1.1" 500 Internal Server Error
ERROR:    Exception in ASGI application
Traceback (most recent call last):
  File "/Users/arturopinzon/Desktop/scAIe - Sistema Agente/scaie_crm/venv/lib/python3.9/site-packages/uvicorn/protocols/http/h11_impl.py", line 403, in run_asgi
    result = await app(  # type: ignore[func-returns-value]
  File "/Users/arturopinzon/Desktop/scAIe - Sistema Agente/scaie_crm/venv/lib/python3.9/site-packages/uvicorn/middleware/proxy_headers.py", line 60, in __call__
    return await self.app(scope, receive, send)
  File "/Users/arturopinzon/Desktop/scAIe - Sistema Agente/scaie_crm/venv/lib/python3.9/site-packages/fastapi/applications.py", line 1054, in __call__
    await super().__call__(scope, receive, send)
  File "/Users/arturopinzon/Desktop/scAIe - Sistema Agente/scaie_crm/venv/lib/python3.9/site-packages/starlette/applications.py", line 113, in __call__
    await self.middleware_stack(scope, receive, send)
  File "/Users/arturopinzon/Desktop/scAIe - Sistema Agente/scaie_crm/venv/lib/python3.9/site-packages/starlette/middleware/errors.py", line 186, in __call__
    raise exc
  File "/Users/arturopinzon/Desktop/scAIe - Sistema Agente/scaie_crm/venv/lib/python3.9/site-packages/starlette/middleware/errors.py", line 164, in __call__
    await self.app(scope, receive, _send)
  File "/Users/arturopinzon/Desktop/scAIe - Sistema Agente/scaie_crm/venv/lib/python3.9/site-packages/starlette/middleware/cors.py", line 85, in __call__
    await self.app(scope, receive, send)
  File "/Users/arturopinzon/Desktop/scAIe - Sistema Agente/scaie_crm/venv/lib/python3.9/site-packages/starlette/middleware/exceptions.py", line 63, in __call__
    await wrap_app_handling_exceptions(self.app, conn)(scope, receive, send)
  File "/Users/arturopinzon/Desktop/scAIe - Sistema Agente/scaie_crm/venv/lib/python3.9/site-packages/starlette/_exception_handler.py", line 53, in wrapped_app
    raise exc
  File "/Users/arturopinzon/Desktop/scAIe - Sistema Agente/scaie_crm/venv/lib/python3.9/site-packages/starlette/_exception_handler.py", line 42, in wrapped_app
    await app(scope, receive, sender)
  File "/Users/arturopinzon/Desktop/scAIe - Sistema Agente/scaie_crm/venv/lib/python3.9/site-packages/starlette/routing.py", line 716, in __call__
    await self.middleware_stack(scope, receive, send)
  File "/Users/arturopinzon/Desktop/scAIe - Sistema Agente/scaie_crm/venv/lib/python3.9/site-packages/starlette/routing.py", line 736, in app
    await route.handle(scope, receive, send)
  File "/Users/arturopinzon/Desktop/scAIe - Sistema Agente/scaie_crm/venv/lib/python3.9/site-packages/starlette/routing.py", line 290, in handle
    await self.app(scope, receive, send)
  File "/Users/arturopinzon/Desktop/scAIe - Sistema Agente/scaie_crm/venv/lib/python3.9/site-packages/starlette/routing.py", line 78, in app
    await wrap_app_handling_exceptions(app, request)(scope, receive, send)
  File "/Users/arturopinzon/Desktop/scAIe - Sistema Agente/scaie_crm/venv/lib/python3.9/site-packages/starlette/_exception_handler.py", line 53, in wrapped_app
    raise exc
  File "/Users/arturopinzon/Desktop/scAIe - Sistema Agente/scaie_crm/venv/lib/python3.9/site-packages/starlette/_exception_handler.py", line 42, in wrapped_app
    await app(scope, receive, sender)
  File "/Users/arturopinzon/Desktop/scAIe - Sistema Agente/scaie_crm/venv/lib/python3.9/site-packages/starlette/routing.py", line 75, in app
    response = await f(request)
  File "/Users/arturopinzon/Desktop/scAIe - Sistema Agente/scaie_crm/venv/lib/python3.9/site-packages/fastapi/routing.py", line 328, in app
    content = await serialize_response(
  File "/Users/arturopinzon/Desktop/scAIe - Sistema Agente/scaie_crm/venv/lib/python3.9/site-packages/fastapi/routing.py", line 177, in serialize_response
    raise ResponseValidationError(
fastapi.exceptions.ResponseValidationError: 10 validation errors:
  {'type': 'string_type', 'loc': ('response', 'contacts', 3, 'phone'), 'msg': 'Input should be a valid string', 'input': None}
  {'type': 'string_type', 'loc': ('response', 'contacts', 4, 'phone'), 'msg': 'Input should be a valid string', 'input': None}
  {'type': 'string_type', 'loc': ('response', 'contacts', 5, 'phone'), 'msg': 'Input should be a valid string', 'input': None}
  {'type': 'string_type', 'loc': ('response', 'contacts', 6, 'phone'), 'msg': 'Input should be a valid string', 'input': None}
  {'type': 'string_type', 'loc': ('response', 'contacts', 7, 'phone'), 'msg': 'Input should be a valid string', 'input': None}
  {'type': 'string_type', 'loc': ('response', 'contacts', 8, 'phone'), 'msg': 'Input should be a valid string', 'input': None}
  {'type': 'string_type', 'loc': ('response', 'contacts', 9, 'phone'), 'msg': 'Input should be a valid string', 'input': None}
  {'type': 'string_type', 'loc': ('response', 'contacts', 10, 'phone'), 'msg': 'Input should be a valid string', 'input': None}
  {'type': 'string_type', 'loc': ('response', 'contacts', 11, 'phone'), 'msg': 'Input should be a valid string', 'input': None}
  {'type': 'string_type', 'loc': ('response', 'contacts', 12, 'phone'), 'msg': 'Input should be a valid string', 'input': None}

INFO:     127.0.0.1:58678 - "GET /api/contacts/?page=1&size=10 HTTP/1.1" 500 Internal Server Error
ERROR:    Exception in ASGI application
Traceback (most recent call last):
  File "/Users/arturopinzon/Desktop/scAIe - Sistema Agente/scaie_crm/venv/lib/python3.9/site-packages/uvicorn/protocols/http/h11_impl.py", line 403, in run_asgi
    result = await app(  # type: ignore[func-returns-value]
  File "/Users/arturopinzon/Desktop/scAIe - Sistema Agente/scaie_crm/venv/lib/python3.9/site-packages/uvicorn/middleware/proxy_headers.py", line 60, in __call__
    return await self.app(scope, receive, send)
  File "/Users/arturopinzon/Desktop/scAIe - Sistema Agente/scaie_crm/venv/lib/python3.9/site-packages/fastapi/applications.py", line 1054, in __call__
    await super().__call__(scope, receive, send)
  File "/Users/arturopinzon/Desktop/scAIe - Sistema Agente/scaie_crm/venv/lib/python3.9/site-packages/starlette/applications.py", line 113, in __call__
    await self.middleware_stack(scope, receive, send)
  File "/Users/arturopinzon/Desktop/scAIe - Sistema Agente/scaie_crm/venv/lib/python3.9/site-packages/starlette/middleware/errors.py", line 186, in __call__
    raise exc
  File "/Users/arturopinzon/Desktop/scAIe - Sistema Agente/scaie_crm/venv/lib/python3.9/site-packages/starlette/middleware/errors.py", line 164, in __call__
    await self.app(scope, receive, _send)
  File "/Users/arturopinzon/Desktop/scAIe - Sistema Agente/scaie_crm/venv/lib/python3.9/site-packages/starlette/middleware/cors.py", line 85, in __call__
    await self.app(scope, receive, send)
  File "/Users/arturopinzon/Desktop/scAIe - Sistema Agente/scaie_crm/venv/lib/python3.9/site-packages/starlette/middleware/exceptions.py", line 63, in __call__
    await wrap_app_handling_exceptions(self.app, conn)(scope, receive, send)
  File "/Users/arturopinzon/Desktop/scAIe - Sistema Agente/scaie_crm/venv/lib/python3.9/site-packages/starlette/_exception_handler.py", line 53, in wrapped_app
    raise exc
  File "/Users/arturopinzon/Desktop/scAIe - Sistema Agente/scaie_crm/venv/lib/python3.9/site-packages/starlette/_exception_handler.py", line 42, in wrapped_app
    await app(scope, receive, sender)
  File "/Users/arturopinzon/Desktop/scAIe - Sistema Agente/scaie_crm/venv/lib/python3.9/site-packages/starlette/routing.py", line 716, in __call__
    await self.middleware_stack(scope, receive, send)
  File "/Users/arturopinzon/Desktop/scAIe - Sistema Agente/scaie_crm/venv/lib/python3.9/site-packages/starlette/routing.py", line 736, in app
    await route.handle(scope, receive, send)
  File "/Users/arturopinzon/Desktop/scAIe - Sistema Agente/scaie_crm/venv/lib/python3.9/site-packages/starlette/routing.py", line 290, in handle
    await self.app(scope, receive, send)
  File "/Users/arturopinzon/Desktop/scAIe - Sistema Agente/scaie_crm/venv/lib/python3.9/site-packages/starlette/routing.py", line 78, in app
    await wrap_app_handling_exceptions(app, request)(scope, receive, send)
  File "/Users/arturopinzon/Desktop/scAIe - Sistema Agente/scaie_crm/venv/lib/python3.9/site-packages/starlette/_exception_handler.py", line 53, in wrapped_app
    raise exc
  File "/Users/arturopinzon/Desktop/scAIe - Sistema Agente/scaie_crm/venv/lib/python3.9/site-packages/starlette/_exception_handler.py", line 42, in wrapped_app
    await app(scope, receive, sender)
  File "/Users/arturopinzon/Desktop/scAIe - Sistema Agente/scaie_crm/venv/lib/python3.9/site-packages/starlette/routing.py", line 75, in app
    response = await f(request)
  File "/Users/arturopinzon/Desktop/scAIe - Sistema Agente/scaie_crm/venv/lib/python3.9/site-packages/fastapi/routing.py", line 328, in app
    content = await serialize_response(
  File "/Users/arturopinzon/Desktop/scAIe - Sistema Agente/scaie_crm/venv/lib/python3.9/site-packages/fastapi/routing.py", line 177, in serialize_response
    raise ResponseValidationError(
fastapi.exceptions.ResponseValidationError: 10 validation errors:
  {'type': 'string_type', 'loc': ('response', 'contacts', 3, 'phone'), 'msg': 'Input should be a valid string', 'input': None}
  {'type': 'string_type', 'loc': ('response', 'contacts', 4, 'phone'), 'msg': 'Input should be a valid string', 'input': None}
  {'type': 'string_type', 'loc': ('response', 'contacts', 5, 'phone'), 'msg': 'Input should be a valid string', 'input': None}
  {'type': 'string_type', 'loc': ('response', 'contacts', 6, 'phone'), 'msg': 'Input should be a valid string', 'input': None}
  {'type': 'string_type', 'loc': ('response', 'contacts', 7, 'phone'), 'msg': 'Input should be a valid string', 'input': None}
  {'type': 'string_type', 'loc': ('response', 'contacts', 8, 'phone'), 'msg': 'Input should be a valid string', 'input': None}
  {'type': 'string_type', 'loc': ('response', 'contacts', 9, 'phone'), 'msg': 'Input should be a valid string', 'input': None}
  {'type': 'string_type', 'loc': ('response', 'contacts', 10, 'phone'), 'msg': 'Input should be a valid string', 'input': None}
  {'type': 'string_type', 'loc': ('response', 'contacts', 11, 'phone'), 'msg': 'Input should be a valid string', 'input': None}
  {'type': 'string_type', 'loc': ('response', 'contacts', 12, 'phone'), 'msg': 'Input should be a valid string', 'input': None}

INFO:     127.0.0.1:58680 - "GET /api/contacts/?page=1&size=10 HTTP/1.1" 500 Internal Server Error
ERROR:    Exception in ASGI application
Traceback (most recent call last):
  File "/Users/arturopinzon/Desktop/scAIe - Sistema Agente/scaie_crm/venv/lib/python3.9/site-packages/uvicorn/protocols/http/h11_impl.py", line 403, in run_asgi
    result = await app(  # type: ignore[func-returns-value]
  File "/Users/arturopinzon/Desktop/scAIe - Sistema Agente/scaie_crm/venv/lib/python3.9/site-packages/uvicorn/middleware/proxy_headers.py", line 60, in __call__
    return await self.app(scope, receive, send)
  File "/Users/arturopinzon/Desktop/scAIe - Sistema Agente/scaie_crm/venv/lib/python3.9/site-packages/fastapi/applications.py", line 1054, in __call__
    await super().__call__(scope, receive, send)
  File "/Users/arturopinzon/Desktop/scAIe - Sistema Agente/scaie_crm/venv/lib/python3.9/site-packages/starlette/applications.py", line 113, in __call__
    await self.middleware_stack(scope, receive, send)
  File "/Users/arturopinzon/Desktop/scAIe - Sistema Agente/scaie_crm/venv/lib/python3.9/site-packages/starlette/middleware/errors.py", line 186, in __call__
    raise exc
  File "/Users/arturopinzon/Desktop/scAIe - Sistema Agente/scaie_crm/venv/lib/python3.9/site-packages/starlette/middleware/errors.py", line 164, in __call__
    await self.app(scope, receive, _send)
  File "/Users/arturopinzon/Desktop/scAIe - Sistema Agente/scaie_crm/venv/lib/python3.9/site-packages/starlette/middleware/cors.py", line 85, in __call__
    await self.app(scope, receive, send)
  File "/Users/arturopinzon/Desktop/scAIe - Sistema Agente/scaie_crm/venv/lib/python3.9/site-packages/starlette/middleware/exceptions.py", line 63, in __call__
    await wrap_app_handling_exceptions(self.app, conn)(scope, receive, send)
  File "/Users/arturopinzon/Desktop/scAIe - Sistema Agente/scaie_crm/venv/lib/python3.9/site-packages/starlette/_exception_handler.py", line 53, in wrapped_app
    raise exc
  File "/Users/arturopinzon/Desktop/scAIe - Sistema Agente/scaie_crm/venv/lib/python3.9/site-packages/starlette/_exception_handler.py", line 42, in wrapped_app
    await app(scope, receive, sender)
  File "/Users/arturopinzon/Desktop/scAIe - Sistema Agente/scaie_crm/venv/lib/python3.9/site-packages/starlette/routing.py", line 716, in __call__
    await self.middleware_stack(scope, receive, send)
  File "/Users/arturopinzon/Desktop/scAIe - Sistema Agente/scaie_crm/venv/lib/python3.9/site-packages/starlette/routing.py", line 736, in app
    await route.handle(scope, receive, send)
  File "/Users/arturopinzon/Desktop/scAIe - Sistema Agente/scaie_crm/venv/lib/python3.9/site-packages/starlette/routing.py", line 290, in handle
    await self.app(scope, receive, send)
  File "/Users/arturopinzon/Desktop/scAIe - Sistema Agente/scaie_crm/venv/lib/python3.9/site-packages/starlette/routing.py", line 78, in app
    await wrap_app_handling_exceptions(app, request)(scope, receive, send)
  File "/Users/arturopinzon/Desktop/scAIe - Sistema Agente/scaie_crm/venv/lib/python3.9/site-packages/starlette/_exception_handler.py", line 53, in wrapped_app
    raise exc
  File "/Users/arturopinzon/Desktop/scAIe - Sistema Agente/scaie_crm/venv/lib/python3.9/site-packages/starlette/_exception_handler.py", line 42, in wrapped_app
    await app(scope, receive, sender)
  File "/Users/arturopinzon/Desktop/scAIe - Sistema Agente/scaie_crm/venv/lib/python3.9/site-packages/starlette/routing.py", line 75, in app
    response = await f(request)
  File "/Users/arturopinzon/Desktop/scAIe - Sistema Agente/scaie_crm/venv/lib/python3.9/site-packages/fastapi/routing.py", line 328, in app
    content = await serialize_response(
  File "/Users/arturopinzon/Desktop/scAIe - Sistema Agente/scaie_crm/venv/lib/python3.9/site-packages/fastapi/routing.py", line 177, in serialize_response
    raise ResponseValidationError(
fastapi.exceptions.ResponseValidationError: 10 validation errors:
  {'type': 'string_type', 'loc': ('response', 'contacts', 3, 'phone'), 'msg': 'Input should be a valid string', 'input': None}
  {'type': 'string_type', 'loc': ('response', 'contacts', 4, 'phone'), 'msg': 'Input should be a valid string', 'input': None}
  {'type': 'string_type', 'loc': ('response', 'contacts', 5, 'phone'), 'msg': 'Input should be a valid string', 'input': None}
  {'type': 'string_type', 'loc': ('response', 'contacts', 6, 'phone'), 'msg': 'Input should be a valid string', 'input': None}
  {'type': 'string_type', 'loc': ('response', 'contacts', 7, 'phone'), 'msg': 'Input should be a valid string', 'input': None}
  {'type': 'string_type', 'loc': ('response', 'contacts', 8, 'phone'), 'msg': 'Input should be a valid string', 'input': None}
  {'type': 'string_type', 'loc': ('response', 'contacts', 9, 'phone'), 'msg': 'Input should be a valid string', 'input': None}
  {'type': 'string_type', 'loc': ('response', 'contacts', 10, 'phone'), 'msg': 'Input should be a valid string', 'input': None}
  {'type': 'string_type', 'loc': ('response', 'contacts', 11, 'phone'), 'msg': 'Input should be a valid string', 'input': None}
  {'type': 'string_type', 'loc': ('response', 'contacts', 12, 'phone'), 'msg': 'Input should be a valid string', 'input': None}

INFO:     127.0.0.1:58682 - "GET /api/contacts/?page=1&size=10 HTTP/1.1" 500 Internal Server Error
ERROR:    Exception in ASGI application
Traceback (most recent call last):
  File "/Users/arturopinzon/Desktop/scAIe - Sistema Agente/scaie_crm/venv/lib/python3.9/site-packages/uvicorn/protocols/http/h11_impl.py", line 403, in run_asgi
    result = await app(  # type: ignore[func-returns-value]
  File "/Users/arturopinzon/Desktop/scAIe - Sistema Agente/scaie_crm/venv/lib/python3.9/site-packages/uvicorn/middleware/proxy_headers.py", line 60, in __call__
    return await self.app(scope, receive, send)
  File "/Users/arturopinzon/Desktop/scAIe - Sistema Agente/scaie_crm/venv/lib/python3.9/site-packages/fastapi/applications.py", line 1054, in __call__
    await super().__call__(scope, receive, send)
  File "/Users/arturopinzon/Desktop/scAIe - Sistema Agente/scaie_crm/venv/lib/python3.9/site-packages/starlette/applications.py", line 113, in __call__
    await self.middleware_stack(scope, receive, send)
  File "/Users/arturopinzon/Desktop/scAIe - Sistema Agente/scaie_crm/venv/lib/python3.9/site-packages/starlette/middleware/errors.py", line 186, in __call__
    raise exc
  File "/Users/arturopinzon/Desktop/scAIe - Sistema Agente/scaie_crm/venv/lib/python3.9/site-packages/starlette/middleware/errors.py", line 164, in __call__
    await self.app(scope, receive, _send)
  File "/Users/arturopinzon/Desktop/scAIe - Sistema Agente/scaie_crm/venv/lib/python3.9/site-packages/starlette/middleware/cors.py", line 85, in __call__
    await self.app(scope, receive, send)
  File "/Users/arturopinzon/Desktop/scAIe - Sistema Agente/scaie_crm/venv/lib/python3.9/site-packages/starlette/middleware/exceptions.py", line 63, in __call__
    await wrap_app_handling_exceptions(self.app, conn)(scope, receive, send)
  File "/Users/arturopinzon/Desktop/scAIe - Sistema Agente/scaie_crm/venv/lib/python3.9/site-packages/starlette/_exception_handler.py", line 53, in wrapped_app
    raise exc
  File "/Users/arturopinzon/Desktop/scAIe - Sistema Agente/scaie_crm/venv/lib/python3.9/site-packages/starlette/_exception_handler.py", line 42, in wrapped_app
    await app(scope, receive, sender)
  File "/Users/arturopinzon/Desktop/scAIe - Sistema Agente/scaie_crm/venv/lib/python3.9/site-packages/starlette/routing.py", line 716, in __call__
    await self.middleware_stack(scope, receive, send)
  File "/Users/arturopinzon/Desktop/scAIe - Sistema Agente/scaie_crm/venv/lib/python3.9/site-packages/starlette/routing.py", line 736, in app
    await route.handle(scope, receive, send)
  File "/Users/arturopinzon/Desktop/scAIe - Sistema Agente/scaie_crm/venv/lib/python3.9/site-packages/starlette/routing.py", line 290, in handle
    await self.app(scope, receive, send)
  File "/Users/arturopinzon/Desktop/scAIe - Sistema Agente/scaie_crm/venv/lib/python3.9/site-packages/starlette/routing.py", line 78, in app
    await wrap_app_handling_exceptions(app, request)(scope, receive, send)
  File "/Users/arturopinzon/Desktop/scAIe - Sistema Agente/scaie_crm/venv/lib/python3.9/site-packages/starlette/_exception_handler.py", line 53, in wrapped_app
    raise exc
  File "/Users/arturopinzon/Desktop/scAIe - Sistema Agente/scaie_crm/venv/lib/python3.9/site-packages/starlette/_exception_handler.py", line 42, in wrapped_app
    await app(scope, receive, sender)
  File "/Users/arturopinzon/Desktop/scAIe - Sistema Agente/scaie_crm/venv/lib/python3.9/site-packages/starlette/routing.py", line 75, in app
    response = await f(request)
  File "/Users/arturopinzon/Desktop/scAIe - Sistema Agente/scaie_crm/venv/lib/python3.9/site-packages/fastapi/routing.py", line 328, in app
    content = await serialize_response(
  File "/Users/arturopinzon/Desktop/scAIe - Sistema Agente/scaie_crm/venv/lib/python3.9/site-packages/fastapi/routing.py", line 177, in serialize_response
    raise ResponseValidationError(
fastapi.exceptions.ResponseValidationError: 10 validation errors:
  {'type': 'string_type', 'loc': ('response', 'contacts', 3, 'phone'), 'msg': 'Input should be a valid string', 'input': None}
  {'type': 'string_type', 'loc': ('response', 'contacts', 4, 'phone'), 'msg': 'Input should be a valid string', 'input': None}
  {'type': 'string_type', 'loc': ('response', 'contacts', 5, 'phone'), 'msg': 'Input should be a valid string', 'input': None}
  {'type': 'string_type', 'loc': ('response', 'contacts', 6, 'phone'), 'msg': 'Input should be a valid string', 'input': None}
  {'type': 'string_type', 'loc': ('response', 'contacts', 7, 'phone'), 'msg': 'Input should be a valid string', 'input': None}
  {'type': 'string_type', 'loc': ('response', 'contacts', 8, 'phone'), 'msg': 'Input should be a valid string', 'input': None}
  {'type': 'string_type', 'loc': ('response', 'contacts', 9, 'phone'), 'msg': 'Input should be a valid string', 'input': None}
  {'type': 'string_type', 'loc': ('response', 'contacts', 10, 'phone'), 'msg': 'Input should be a valid string', 'input': None}
  {'type': 'string_type', 'loc': ('response', 'contacts', 11, 'phone'), 'msg': 'Input should be a valid string', 'input': None}
  {'type': 'string_type', 'loc': ('response', 'contacts', 12, 'phone'), 'msg': 'Input should be a valid string', 'input': None}

INFO:     127.0.0.1:58684 - "GET /api/contacts/?page=1&size=10 HTTP/1.1" 500 Internal Server Error
ERROR:    Exception in ASGI application
Traceback (most recent call last):
  File "/Users/arturopinzon/Desktop/scAIe - Sistema Agente/scaie_crm/venv/lib/python3.9/site-packages/uvicorn/protocols/http/h11_impl.py", line 403, in run_asgi
    result = await app(  # type: ignore[func-returns-value]
  File "/Users/arturopinzon/Desktop/scAIe - Sistema Agente/scaie_crm/venv/lib/python3.9/site-packages/uvicorn/middleware/proxy_headers.py", line 60, in __call__
    return await self.app(scope, receive, send)
  File "/Users/arturopinzon/Desktop/scAIe - Sistema Agente/scaie_crm/venv/lib/python3.9/site-packages/fastapi/applications.py", line 1054, in __call__
    await super().__call__(scope, receive, send)
  File "/Users/arturopinzon/Desktop/scAIe - Sistema Agente/scaie_crm/venv/lib/python3.9/site-packages/starlette/applications.py", line 113, in __call__
    await self.middleware_stack(scope, receive, send)
  File "/Users/arturopinzon/Desktop/scAIe - Sistema Agente/scaie_crm/venv/lib/python3.9/site-packages/starlette/middleware/errors.py", line 186, in __call__
    raise exc
  File "/Users/arturopinzon/Desktop/scAIe - Sistema Agente/scaie_crm/venv/lib/python3.9/site-packages/starlette/middleware/errors.py", line 164, in __call__
    await self.app(scope, receive, _send)
  File "/Users/arturopinzon/Desktop/scAIe - Sistema Agente/scaie_crm/venv/lib/python3.9/site-packages/starlette/middleware/cors.py", line 85, in __call__
    await self.app(scope, receive, send)
  File "/Users/arturopinzon/Desktop/scAIe - Sistema Agente/scaie_crm/venv/lib/python3.9/site-packages/starlette/middleware/exceptions.py", line 63, in __call__
    await wrap_app_handling_exceptions(self.app, conn)(scope, receive, send)
  File "/Users/arturopinzon/Desktop/scAIe - Sistema Agente/scaie_crm/venv/lib/python3.9/site-packages/starlette/_exception_handler.py", line 53, in wrapped_app
    raise exc
  File "/Users/arturopinzon/Desktop/scAIe - Sistema Agente/scaie_crm/venv/lib/python3.9/site-packages/starlette/_exception_handler.py", line 42, in wrapped_app
    await app(scope, receive, sender)
  File "/Users/arturopinzon/Desktop/scAIe - Sistema Agente/scaie_crm/venv/lib/python3.9/site-packages/starlette/routing.py", line 716, in __call__
    await self.middleware_stack(scope, receive, send)
  File "/Users/arturopinzon/Desktop/scAIe - Sistema Agente/scaie_crm/venv/lib/python3.9/site-packages/starlette/routing.py", line 736, in app
    await route.handle(scope, receive, send)
  File "/Users/arturopinzon/Desktop/scAIe - Sistema Agente/scaie_crm/venv/lib/python3.9/site-packages/starlette/routing.py", line 290, in handle
    await self.app(scope, receive, send)
  File "/Users/arturopinzon/Desktop/scAIe - Sistema Agente/scaie_crm/venv/lib/python3.9/site-packages/starlette/routing.py", line 78, in app
    await wrap_app_handling_exceptions(app, request)(scope, receive, send)
  File "/Users/arturopinzon/Desktop/scAIe - Sistema Agente/scaie_crm/venv/lib/python3.9/site-packages/starlette/_exception_handler.py", line 53, in wrapped_app
    raise exc
  File "/Users/arturopinzon/Desktop/scAIe - Sistema Agente/scaie_crm/venv/lib/python3.9/site-packages/starlette/_exception_handler.py", line 42, in wrapped_app
    await app(scope, receive, sender)
  File "/Users/arturopinzon/Desktop/scAIe - Sistema Agente/scaie_crm/venv/lib/python3.9/site-packages/starlette/routing.py", line 75, in app
    response = await f(request)
  File "/Users/arturopinzon/Desktop/scAIe - Sistema Agente/scaie_crm/venv/lib/python3.9/site-packages/fastapi/routing.py", line 328, in app
    content = await serialize_response(
  File "/Users/arturopinzon/Desktop/scAIe - Sistema Agente/scaie_crm/venv/lib/python3.9/site-packages/fastapi/routing.py", line 177, in serialize_response
    raise ResponseValidationError(
fastapi.exceptions.ResponseValidationError: 10 validation errors:
  {'type': 'string_type', 'loc': ('response', 'contacts', 3, 'phone'), 'msg': 'Input should be a valid string', 'input': None}
  {'type': 'string_type', 'loc': ('response', 'contacts', 4, 'phone'), 'msg': 'Input should be a valid string', 'input': None}
  {'type': 'string_type', 'loc': ('response', 'contacts', 5, 'phone'), 'msg': 'Input should be a valid string', 'input': None}
  {'type': 'string_type', 'loc': ('response', 'contacts', 6, 'phone'), 'msg': 'Input should be a valid string', 'input': None}
  {'type': 'string_type', 'loc': ('response', 'contacts', 7, 'phone'), 'msg': 'Input should be a valid string', 'input': None}
  {'type': 'string_type', 'loc': ('response', 'contacts', 8, 'phone'), 'msg': 'Input should be a valid string', 'input': None}
  {'type': 'string_type', 'loc': ('response', 'contacts', 9, 'phone'), 'msg': 'Input should be a valid string', 'input': None}
  {'type': 'string_type', 'loc': ('response', 'contacts', 10, 'phone'), 'msg': 'Input should be a valid string', 'input': None}
  {'type': 'string_type', 'loc': ('response', 'contacts', 11, 'phone'), 'msg': 'Input should be a valid string', 'input': None}
  {'type': 'string_type', 'loc': ('response', 'contacts', 12, 'phone'), 'msg': 'Input should be a valid string', 'input': None}

